Workbook

Sheet README & Guide
B2: GANTT CHART INTERAKTIF KELOMPOK
B3: Panduan Penggunaan Template untuk Koordinasi Tugas Kuliah
B5: Cara Penggunaan Template
B7: 1. Set Tanggal Mulai | C7: Buka tab 'Gantt Chart Schedule' lalu isi tanggal mulai proyek di sel C4. Kalender sumbu waktu sebelah kanan akan bergeser otomatis.
B8: 2. Input Daftar Tugas | C8: Isi kolom Tugas (B12 dst) beserta PIC yang bertanggung jawab (C12 dst) pada tabel jadwal.
B9: 3. Input Tanggal Tugas | C9: Isi 'Start Date' dan 'End Date' tugas. Durasi (hari) akan dihitung otomatis oleh formula Excel.
B10: 4. Update Progress | C10: Masukkan persentase penyelesaian tugas di kolom '% Progress' (G12 dst, contoh: isi 0.5 untuk 50%). Status akan terupdate otomatis (Not Started, In Progress, Completed).
B11: 5. Pantau Gantt Chart | C11: Gantt Chart di kolom J ke kanan akan terarsir secara otomatis berdasarkan rentang tanggal tugas.
B12: 6. Pantau Dashboard KPI | C12: Buka tab 'KPI Dashboard' untuk melihat perkembangan keseluruhan proyek, sisa tugas, dan beban kerja per anggota kelompok.
B14: Shortcut Excel Produktif
B16: Shortcut | C16: Fungsi & Kegunaan
B17: Ctrl + ; | C17: Memasukkan tanggal hari ini secara instan.
B18: F4 | C18: Mengunci rumus menjadi absolut (tanda $) saat mengedit formula.
B19: Alt + Enter | C19: Membuat baris baru di dalam satu sel yang sama (wrap text manual).
B20: Ctrl + Z | C20: Membatalkan kesalahan edit terakhir (Undo).

Sheet KPI Dashboard
B2: DASHBOARD PERKEMBANGAN PROYEK
B3: Rekapitulasi Kinerja Tugas Kelompok secara Real-Time
B5: TOTAL TUGAS KELOMPOK | E5: TUGAS SELESAI | H5: SEDANG DIKERJAKAN
B6: =COUNTA('Gantt Chart Schedule'!B12:B50) | E6: =COUNTIF('Gantt Chart Schedule'!H12:H50, "Completed") | H6: =COUNTIF('Gantt Chart Schedule'!H12:H50, "In Progress")
B9: TOTAL PROGRESS PROYEK: | E9: =AVERAGE('Gantt Chart Schedule'!G12:G50)
B12: BEBAN KERJA & PROGRESS ANGGOTA KELOMPOK
B14: Nama Anggota (PIC) | C14: Jumlah Tugas | E14: Rata-rata Progress
B15: Bariandono | C15: =COUNTIF('Gantt Chart Schedule'!C$12:C$50, B15) | E15: =IF(C15=0, 0, AVERAGEIFS('Gantt Chart Schedule'!G$12:G$50, 'Gantt Chart Schedule'!C$12:C$50, B15))
B16: Ajie | C16: =COUNTIF('Gantt Chart Schedule'!C$12:C$50, B16) | E16: =IF(C16=0, 0, AVERAGEIFS('Gantt Chart Schedule'!G$12:G$50, 'Gantt Chart Schedule'!C$12:C$50, B16))
B17: Sarah | C17: =COUNTIF('Gantt Chart Schedule'!C$12:C$50, B17) | E17: =IF(C17=0, 0, AVERAGEIFS('Gantt Chart Schedule'!G$12:G$50, 'Gantt Chart Schedule'!C$12:C$50, B17))
B18: Dewi | C18: =COUNTIF('Gantt Chart Schedule'!C$12:C$50, B18) | E18: =IF(C18=0, 0, AVERAGEIFS('Gantt Chart Schedule'!G$12:G$50, 'Gantt Chart Schedule'!C$12:C$50, B18))

Sheet Gantt Chart Schedule
B2: JADWAL TUGAS & GANTT CHART KELOMPOK
B4: Project Start Date: | C4: 2026-06-15
B5: Total Project Duration: | C5: =MAX(E12:E50)-MIN(D12:D50)+1
J9: H-1 | K9: H-2 | L9: H-3 | M9: H-4 | N9: H-5 | O9: H-6 | P9: H-7 | Q9: H-8 | R9: H-9 | S9: H-10 | T9: H-11 | U9: H-12 | V9: H-13 | W9: H-14 | X9: H-15 | Y9: H-16 | Z9: H-17 | AA9: H-18 | AB9: H-19 | AC9: H-20 | AD9: H-21 | AE9: H-22 | AF9: H-23 | AG9: H-24 | AH9: H-25 | AI9: H-26 | AJ9: H-27 | AK9: H-28 | AL9: H-29 | AM9: H-30
J10: =$C$4 | K10: =J10+1 | L10: =K10+1 | M10: =L10+1 | N10: =M10+1 | O10: =N10+1 | P10: =O10+1 | Q10: =P10+1 | R10: =Q10+1 | ... AM10: =AL10+1
A11: ID | B11: Nama Tugas / Kegiatan | C11: PIC (Anggota) | D11: Start Date | E11: End Date | F11: Durasi | G11: Progress | H11: Status
A12: 1 | B12: Riset Topik & Cari Masalah | C12: Bariandono | D12: 2026-06-15 | E12: 2026-06-18 | F12: =IF(OR(ISBLANK(D12), ISBLANK(E12)), "", E12-D12+1) | G12: 1 | H12: =IF(ISBLANK(B12), "", IF(G12=0, "Not Started", IF(G12=1, "Completed", "In Progress"))) | J12: =IF(AND(NOT(ISBLANK(D12)), J$10>=D12, J$10<=E12), "█", "") | K12: =IF(AND(NOT(ISBLANK(D12)), K$10>=D12, K$10<=E12), "█", "") | L12: =IF(AND(NOT(ISBLANK(D12)), L$10>=D12, L$10<=E12), "█", "") | M12: =IF(AND(NOT(ISBLANK(D12)), M$10>=D12, M$10<=E12), "█", "") | N12: =IF(AND(NOT(ISBLANK(D12)), N$10>=D12, N$10<=E12), "█", "") | O12: =IF(AND(NOT(ISBLANK(D12)), O$10>=D12, O$10<=E12), "█", "") | P12: =IF(AND(NOT(ISBLANK(D12)), P$10>=D12, P$10<=E12), "█", "") | Q12: =IF(AND(NOT(ISBLANK(D12)), Q$10>=D12, Q$10<=E12), "█", "") | R12: =IF(AND(NOT(ISBLANK(D12)), R$10>=D12, R$10<=E12), "█", "") | S12: =IF(AND(NOT(ISBLANK(D12)), S$10>=D12, S$10<=E12), "█", "") | T12: =IF(AND(NOT(ISBLANK(D12)), T$10>=D12, T$10<=E12), "█", "") | U12: =IF(AND(NOT(ISBLANK(D12)), U$10>=D12, U$10<=E12), "█", "") | V12: =IF(AND(NOT(ISBLANK(D12)), V$10>=D12, V$10<=E12), "█", "") | W12: =IF(AND(NOT(ISBLANK(D12)), W$10>=D12, W$10<=E12), "█", "") | X12: =IF(AND(NOT(ISBLANK(D12)), X$10>=D12, X$10<=E12), "█", "") | Y12: =IF(AND(NOT(ISBLANK(D12)), Y$10>=D12, Y$10<=E12), "█", "") | Z12: =IF(AND(NOT(ISBLANK(D12)), Z$10>=D12, Z$10<=E12), "█", "") | AA12: =IF(AND(NOT(ISBLANK(D12)), AA$10>=D12, AA$10<=E12), "█", "") | AB12: =IF(AND(NOT(ISBLANK(D12)), AB$10>=D12, AB$10<=E12), "█", "") | AC12: =IF(AND(NOT(ISBLANK(D12)), AC$10>=D12, AC$10<=E12), "█", "") | AD12: =IF(AND(NOT(ISBLANK(D12)), AD$10>=D12, AD$10<=E12), "█", "") | AE12: =IF(AND(NOT(ISBLANK(D12)), AE$10>=D12, AE$10<=E12), "█", "") | AF12: =IF(AND(NOT(ISBLANK(D12)), AF$10>=D12, AF$10<=E12), "█", "") | AG12: =IF(AND(NOT(ISBLANK(D12)), AG$10>=D12, AG$10<=E12), "█", "") | AH12: =IF(AND(NOT(ISBLANK(D12)), AH$10>=D12, AH$10<=E12), "█", "") | AI12: =IF(AND(NOT(ISBLANK(D12)), AI$10>=D12, AI$10<=E12), "█", "") | AJ12: =IF(AND(NOT(ISBLANK(D12)), AJ$10>=D12, AJ$10<=E12), "█", "") | AK12: =IF(AND(NOT(ISBLANK(D12)), AK$10>=D12, AK$10<=E12), "█", "") | AL12: =IF(AND(NOT(ISBLANK(D12)), AL$10>=D12, AL$10<=E12), "█", "") | AM12: =IF(AND(NOT(ISBLANK(D12)), AM$10>=D12, AM$10<=E12), "█", "")
A13: 2 | B13: Desain Outline Proyek | C13: Ajie | D13: 2026-06-19 | E13: 2026-06-21 | F13: =IF(OR(ISBLANK(D13), ISBLANK(E13)), "", E13-D13+1) | G13: 0.8 | H13: =IF(ISBLANK(B13), "", IF(G13=0, "Not Started", IF(G13=1, "Completed", "In Progress"))) | J13: =IF(AND(NOT(ISBLANK(D13)), J$10>=D13, J$10<=E13), "█", "") | K13: =IF(AND(NOT(ISBLANK(D13)), K$10>=D13, K$10<=E13), "█", "") | L13: =IF(AND(NOT(ISBLANK(D13)), L$10>=D13, L$10<=E13), "█", "") | M13: =IF(AND(NOT(ISBLANK(D13)), M$10>=D13, M$10<=E13), "█", "") | N13: =IF(AND(NOT(ISBLANK(D13)), N$10>=D13, N$10<=E13), "█", "") | O13: =IF(AND(NOT(ISBLANK(D13)), O$10>=D13, O$10<=E13), "█", "") | P13: =IF(AND(NOT(ISBLANK(D13)), P$10>=D13, P$10<=E13), "█", "") | Q13: =IF(AND(NOT(ISBLANK(D13)), Q$10>=D13, Q$10<=E13), "█", "") | R13: =IF(AND(NOT(ISBLANK(D13)), R$10>=D13, R$10<=E13), "█", "") | S13: =IF(AND(NOT(ISBLANK(D13)), S$10>=D13, S$10<=E13), "█", "") | T13: =IF(AND(NOT(ISBLANK(D13)), T$10>=D13, T$10<=E13), "█", "") | U13: =IF(AND(NOT(ISBLANK(D13)), U$10>=D13, U$10<=E13), "█", "") | V13: =IF(AND(NOT(ISBLANK(D13)), V$10>=D13, V$10<=E13), "█", "") | W13: =IF(AND(NOT(ISBLANK(D13)), W$10>=D13, W$10<=E13), "█", "") | X13: =IF(AND(NOT(ISBLANK(D13)), X$10>=D13, X$10<=E13), "█", "") | Y13: =IF(AND(NOT(ISBLANK(D13)), Y$10>=D13, Y$10<=E13), "█", "") | Z13: =IF(AND(NOT(ISBLANK(D13)), Z$10>=D13, Z$10<=E13), "█", "") | AA13: =IF(AND(NOT(ISBLANK(D13)), AA$10>=D13, AA$10<=E13), "█", "") | AB13: =IF(AND(NOT(ISBLANK(D13)), AB$10>=D13, AB$10<=E13), "█", "") | AC13: =IF(AND(NOT(ISBLANK(D13)), AC$10>=D13, AC$10<=E13), "█", "") | AD13: =IF(AND(NOT(ISBLANK(D13)), AD$10>=D13, AD$10<=E13), "█", "") | AE13: =IF(AND(NOT(ISBLANK(D13)), AE$10>=D13, AE$10<=E13), "█", "") | AF13: =IF(AND(NOT(ISBLANK(D13)), AF$10>=D13, AF$10<=E13), "█", "") | AG13: =IF(AND(NOT(ISBLANK(D13)), AG$10>=D13, AG$10<=E13), "█", "") | AH13: =IF(AND(NOT(ISBLANK(D13)), AH$10>=D13, AH$10<=E13), "█", "") | AI13: =IF(AND(NOT(ISBLANK(D13)), AI$10>=D13, AI$10<=E13), "█", "") | AJ13: =IF(AND(NOT(ISBLANK(D13)), AJ$10>=D13, AJ$10<=E13), "█", "") | AK13: =IF(AND(NOT(ISBLANK(D13)), AK$10>=D13, AK$10<=E13), "█", "") | AL13: =IF(AND(NOT(ISBLANK(D13)), AL$10>=D13, AL$10<=E13), "█", "") | AM13: =IF(AND(NOT(ISBLANK(D13)), AM$10>=D13, AM$10<=E13), "█", "")
A14: 3 | B14: Pengumpulan Data Kuesioner | C14: Sarah | D14: 2026-06-22 | E14: 2026-06-27 | F14: =IF(OR(ISBLANK(D14), ISBLANK(E14)), "", E14-D14+1) | G14: 0.3 | H14: =IF(ISBLANK(B14), "", IF(G14=0, "Not Started", IF(G14=1, "Completed", "In Progress"))) | J14: =IF(AND(NOT(ISBLANK(D14)), J$10>=D14, J$10<=E14), "█", "") | K14: =IF(AND(NOT(ISBLANK(D14)), K$10>=D14, K$10<=E14), "█", "") | L14: =IF(AND(NOT(ISBLANK(D14)), L$10>=D14, L$10<=E14), "█", "") | M14: =IF(AND(NOT(ISBLANK(D14)), M$10>=D14, M$10<=E14), "█", "") | N14: =IF(AND(NOT(ISBLANK(D14)), N$10>=D14, N$10<=E14), "█", "") | O14: =IF(AND(NOT(ISBLANK(D14)), O$10>=D14, O$10<=E14), "█", "") | P14: =IF(AND(NOT(ISBLANK(D14)), P$10>=D14, P$10<=E14), "█", "") | Q14: =IF(AND(NOT(ISBLANK(D14)), Q$10>=D14, Q$10<=E14), "█", "") | R14: =IF(AND(NOT(ISBLANK(D14)), R$10>=D14, R$10<=E14), "█", "") | S14: =IF(AND(NOT(ISBLANK(D14)), S$10>=D14, S$10<=E14), "█", "") | T14: =IF(AND(NOT(ISBLANK(D14)), T$10>=D14, T$10<=E14), "█", "") | U14: =IF(AND(NOT(ISBLANK(D14)), U$10>=D14, U$10<=E14), "█", "") | V14: =IF(AND(NOT(ISBLANK(D14)), V$10>=D14, V$10<=E14), "█", "") | W14: =IF(AND(NOT(ISBLANK(D14)), W$10>=D14, W$10<=E14), "█", "") | X14: =IF(AND(NOT(ISBLANK(D14)), X$10>=D14, X$10<=E14), "█", "") | Y14: =IF(AND(NOT(ISBLANK(D14)), Y$10>=D14, Y$10<=E14), "█", "") | Z14: =IF(AND(NOT(ISBLANK(D14)), Z$10>=D14, Z$10<=E14), "█", "") | AA14: =IF(AND(NOT(ISBLANK(D14)), AA$10>=D14, AA$10<=E14), "█", "") | AB14: =IF(AND(NOT(ISBLANK(D14)), AB$10>=D14, AB$10<=E14), "█", "") | AC14: =IF(AND(NOT(ISBLANK(D14)), AC$10>=D14, AC$10<=E14), "█", "") | AD14: =IF(AND(NOT(ISBLANK(D14)), AD$10>=D14, AD$10<=E14), "█", "") | AE14: =IF(AND(NOT(ISBLANK(D14)), AE$10>=D14, AE$10<=E14), "█", "") | AF14: =IF(AND(NOT(ISBLANK(D14)), AF$10>=D14, AF$10<=E14), "█", "") | AG14: =IF(AND(NOT(ISBLANK(D14)), AG$10>=D14, AG$10<=E14), "█", "") | AH14: =IF(AND(NOT(ISBLANK(D14)), AH$10>=D14, AH$10<=E14), "█", "") | AI14: =IF(AND(NOT(ISBLANK(D14)), AI$10>=D14, AI$10<=E14), "█", "") | AJ14: =IF(AND(NOT(ISBLANK(D14)), AJ$10>=D14, AJ$10<=E14), "█", "") | AK14: =IF(AND(NOT(ISBLANK(D14)), AK$10>=D14, AK$10<=E14), "█", "") | AL14: =IF(AND(NOT(ISBLANK(D14)), AL$10>=D14, AL$10<=E14), "█", "") | AM14: =IF(AND(NOT(ISBLANK(D14)), AM$10>=D14, AM$10<=E14), "█", "")
A15: 4 | B15: Olahan Data SPSS/Stata | C15: Dewi | D15: 2026-06-28 | E15: 2026-06-30 | F15: =IF(OR(ISBLANK(D15), ISBLANK(E15)), "", E15-D15+1) | G15: 0 | H15: =IF(ISBLANK(B15), "", IF(G15=0, "Not Started", IF(G15=1, "Completed", "In Progress"))) | J15: =IF(AND(NOT(ISBLANK(D15)), J$10>=D15, J$10<=E15), "█", "") | K15: =IF(AND(NOT(ISBLANK(D15)), K$10>=D15, K$10<=E15), "█", "") | L15: =IF(AND(NOT(ISBLANK(D15)), L$10>=D15, L$10<=E15), "█", "") | M15: =IF(AND(NOT(ISBLANK(D15)), M$10>=D15, M$10<=E15), "█", "") | N15: =IF(AND(NOT(ISBLANK(D15)), N$10>=D15, N$10<=E15), "█", "") | O15: =IF(AND(NOT(ISBLANK(D15)), O$10>=D15, O$10<=E15), "█", "") | P15: =IF(AND(NOT(ISBLANK(D15)), P$10>=D15, P$10<=E15), "█", "") | Q15: =IF(AND(NOT(ISBLANK(D15)), Q$10>=D15, Q$10<=E15), "█", "") | R15: =IF(AND(NOT(ISBLANK(D15)), R$10>=D15, R$10<=E15), "█", "") | S15: =IF(AND(NOT(ISBLANK(D15)), S$10>=D15, S$10<=E15), "█", "") | T15: =IF(AND(NOT(ISBLANK(D15)), T$10>=D15, T$10<=E15), "█", "") | U15: =IF(AND(NOT(ISBLANK(D15)), U$10>=D15, U$10<=E15), "█", "") | V15: =IF(AND(NOT(ISBLANK(D15)), V$10>=D15, V$10<=E15), "█", "") | W15: =IF(AND(NOT(ISBLANK(D15)), W$10>=D15, W$10<=E15), "█", "") | X15: =IF(AND(NOT(ISBLANK(D15)), X$10>=D15, X$10<=E15), "█", "") | Y15: =IF(AND(NOT(ISBLANK(D15)), Y$10>=D15, Y$10<=E15), "█", "") | Z15: =IF(AND(NOT(ISBLANK(D15)), Z$10>=D15, Z$10<=E15), "█", "") | AA15: =IF(AND(NOT(ISBLANK(D15)), AA$10>=D15, AA$10<=E15), "█", "") | AB15: =IF(AND(NOT(ISBLANK(D15)), AB$10>=D15, AB$10<=E15), "█", "") | AC15: =IF(AND(NOT(ISBLANK(D15)), AC$10>=D15, AC$10<=E15), "█", "") | AD15: =IF(AND(NOT(ISBLANK(D15)), AD$10>=D15, AD$10<=E15), "█", "") | AE15: =IF(AND(NOT(ISBLANK(D15)), AE$10>=D15, AE$10<=E15), "█", "") | AF15: =IF(AND(NOT(ISBLANK(D15)), AF$10>=D15, AF$10<=E15), "█", "") | AG15: =IF(AND(NOT(ISBLANK(D15)), AG$10>=D15, AG$10<=E15), "█", "") | AH15: =IF(AND(NOT(ISBLANK(D15)), AH$10>=D15, AH$10<=E15), "█", "") | AI15: =IF(AND(NOT(ISBLANK(D15)), AI$10>=D15, AI$10<=E15), "█", "") | AJ15: =IF(AND(NOT(ISBLANK(D15)), AJ$10>=D15, AJ$10<=E15), "█", "") | AK15: =IF(AND(NOT(ISBLANK(D15)), AK$10>=D15, AK$10<=E15), "█", "") | AL15: =IF(AND(NOT(ISBLANK(D15)), AL$10>=D15, AL$10<=E15), "█", "") | AM15: =IF(AND(NOT(ISBLANK(D15)), AM$10>=D15, AM$10<=E15), "█", "")
A16: 5 | B16: Penyusunan Draf Bab I-III | C16: Bariandono | D16: 2026-07-01 | E16: 2026-07-05 | F16: =IF(OR(ISBLANK(D16), ISBLANK(E16)), "", E16-D16+1) | G16: 0 | H16: =IF(ISBLANK(B16), "", IF(G16=0, "Not Started", IF(G16=1, "Completed", "In Progress"))) | J16: =IF(AND(NOT(ISBLANK(D16)), J$10>=D16, J$10<=E16), "█", "") | K16: =IF(AND(NOT(ISBLANK(D16)), K$10>=D16, K$10<=E16), "█", "") | L16: =IF(AND(NOT(ISBLANK(D16)), L$10>=D16, L$10<=E16), "█", "") | M16: =IF(AND(NOT(ISBLANK(D16)), M$10>=D16, M$10<=E16), "█", "") | N16: =IF(AND(NOT(ISBLANK(D16)), N$10>=D16, N$10<=E16), "█", "") | O16: =IF(AND(NOT(ISBLANK(D16)), O$10>=D16, O$10<=E16), "█", "") | P16: =IF(AND(NOT(ISBLANK(D16)), P$10>=D16, P$10<=E16), "█", "") | Q16: =IF(AND(NOT(ISBLANK(D16)), Q$10>=D16, Q$10<=E16), "█", "") | R16: =IF(AND(NOT(ISBLANK(D16)), R$10>=D16, R$10<=E16), "█", "") | S16: =IF(AND(NOT(ISBLANK(D16)), S$10>=D16, S$10<=E16), "█", "") | T16: =IF(AND(NOT(ISBLANK(D16)), T$10>=D16, T$10<=E16), "█", "") | U16: =IF(AND(NOT(ISBLANK(D16)), U$10>=D16, U$10<=E16), "█", "") | V16: =IF(AND(NOT(ISBLANK(D16)), V$10>=D16, V$10<=E16), "█", "") | W16: =IF(AND(NOT(ISBLANK(D16)), W$10>=D16, W$10<=E16), "█", "") | X16: =IF(AND(NOT(ISBLANK(D16)), X$10>=D16, X$10<=E16), "█", "") | Y16: =IF(AND(NOT(ISBLANK(D16)), Y$10>=D16, Y$10<=E16), "█", "") | Z16: =IF(AND(NOT(ISBLANK(D16)), Z$10>=D16, Z$10<=E16), "█", "") | AA16: =IF(AND(NOT(ISBLANK(D16)), AA$10>=D16, AA$10<=E16), "█", "") | AB16: =IF(AND(NOT(ISBLANK(D16)), AB$10>=D16, AB$10<=E16), "█", "") | AC16: =IF(AND(NOT(ISBLANK(D16)), AC$10>=D16, AC$10<=E16), "█", "") | AD16: =IF(AND(NOT(ISBLANK(D16)), AD$10>=D16, AD$10<=E16), "█", "") | AE16: =IF(AND(NOT(ISBLANK(D16)), AE$10>=D16, AE$10<=E16), "█", "") | AF16: =IF(AND(NOT(ISBLANK(D16)), AF$10>=D16, AF$10<=E16), "█", "") | AG16: =IF(AND(NOT(ISBLANK(D16)), AG$10>=D16, AG$10<=E16), "█", "") | AH16: =IF(AND(NOT(ISBLANK(D16)), AH$10>=D16, AH$10<=E16), "█", "") | AI16: =IF(AND(NOT(ISBLANK(D16)), AI$10>=D16, AI$10<=E16), "█", "") | AJ16: =IF(AND(NOT(ISBLANK(D16)), AJ$10>=D16, AJ$10<=E16), "█", "") | AK16: =IF(AND(NOT(ISBLANK(D16)), AK$10>=D16, AK$10<=E16), "█", "") | AL16: =IF(AND(NOT(ISBLANK(D16)), AL$10>=D16, AL$10<=E16), "█", "") | AM16: =IF(AND(NOT(ISBLANK(D16)), AM$10>=D16, AM$10<=E16), "█", "")
A17: 6 | B17: Redesain PPT Sidang Sempro | C17: Ajie | D17: 2026-07-06 | E17: 2026-07-10 | F17: =IF(OR(ISBLANK(D17), ISBLANK(E17)), "", E17-D17+1) | G17: 0 | H17: =IF(ISBLANK(B17), "", IF(G17=0, "Not Started", IF(G17=1, "Completed", "In Progress"))) | J17: =IF(AND(NOT(ISBLANK(D17)), J$10>=D17, J$10<=E17), "█", "") | K17: =IF(AND(NOT(ISBLANK(D17)), K$10>=D17, K$10<=E17), "█", "") | L17: =IF(AND(NOT(ISBLANK(D17)), L$10>=D17, L$10<=E17), "█", "") | M17: =IF(AND(NOT(ISBLANK(D17)), M$10>=D17, M$10<=E17), "█", "") | N17: =IF(AND(NOT(ISBLANK(D17)), N$10>=D17, N$10<=E17), "█", "") | O17: =IF(AND(NOT(ISBLANK(D17)), O$10>=D17, O$10<=E17), "█", "") | P17: =IF(AND(NOT(ISBLANK(D17)), P$10>=D17, P$10<=E17), "█", "") | Q17: =IF(AND(NOT(ISBLANK(D17)), Q$10>=D17, Q$10<=E17), "█", "") | R17: =IF(AND(NOT(ISBLANK(D17)), R$10>=D17, R$10<=E17), "█", "") | S17: =IF(AND(NOT(ISBLANK(D17)), S$10>=D17, S$10<=E17), "█", "") | T17: =IF(AND(NOT(ISBLANK(D17)), T$10>=D17, T$10<=E17), "█", "") | U17: =IF(AND(NOT(ISBLANK(D17)), U$10>=D17, U$10<=E17), "█", "") | V17: =IF(AND(NOT(ISBLANK(D17)), V$10>=D17, V$10<=E17), "█", "") | W17: =IF(AND(NOT(ISBLANK(D17)), W$10>=D17, W$10<=E17), "█", "") | X17: =IF(AND(NOT(ISBLANK(D17)), X$10>=D17, X$10<=E17), "█", "") | Y17: =IF(AND(NOT(ISBLANK(D17)), Y$10>=D17, Y$10<=E17), "█", "") | Z17: =IF(AND(NOT(ISBLANK(D17)), Z$10>=D17, Z$10<=E17), "█", "") | AA17: =IF(AND(NOT(ISBLANK(D17)), AA$10>=D17, AA$10<=E17), "█", "") | AB17: =IF(AND(NOT(ISBLANK(D17)), AB$10>=D17, AB$10<=E17), "█", "") | AC17: =IF(AND(NOT(ISBLANK(D17)), AC$10>=D17, AC$10<=E17), "█", "") | AD17: =IF(AND(NOT(ISBLANK(D17)), AD$10>=D17, AD$10<=E17), "█", "") | AE17: =IF(AND(NOT(ISBLANK(D17)), AE$10>=D17, AE$10<=E17), "█", "") | AF17: =IF(AND(NOT(ISBLANK(D17)), AF$10>=D17, AF$10<=E17), "█", "") | AG17: =IF(AND(NOT(ISBLANK(D17)), AG$10>=D17, AG$10<=E17), "█", "") | AH17: =IF(AND(NOT(ISBLANK(D17)), AH$10>=D17, AH$10<=E17), "█", "") | AI17: =IF(AND(NOT(ISBLANK(D17)), AI$10>=D17, AI$10<=E17), "█", "") | AJ17: =IF(AND(NOT(ISBLANK(D17)), AJ$10>=D17, AJ$10<=E17), "█", "") | AK17: =IF(AND(NOT(ISBLANK(D17)), AK$10>=D17, AK$10<=E17), "█", "") | AL17: =IF(AND(NOT(ISBLANK(D17)), AL$10>=D17, AL$10<=E17), "█", "") | AM17: =IF(AND(NOT(ISBLANK(D17)), AM$10>=D17, AM$10<=E17), "█", "")
A18: 7 | B18: Review Plagiasi & Turnitin | C18: Sarah | D18: 2026-07-11 | E18: 2026-07-13 | F18: =IF(OR(ISBLANK(D18), ISBLANK(E18)), "", E18-D18+1) | G18: 0 | H18: =IF(ISBLANK(B18), "", IF(G18=0, "Not Started", IF(G18=1, "Completed", "In Progress"))) | J18: =IF(AND(NOT(ISBLANK(D18)), J$10>=D18, J$10<=E18), "█", "") | K18: =IF(AND(NOT(ISBLANK(D18)), K$10>=D18, K$10<=E18), "█", "") | L18: =IF(AND(NOT(ISBLANK(D18)), L$10>=D18, L$10<=E18), "█", "") | M18: =IF(AND(NOT(ISBLANK(D18)), M$10>=D18, M$10<=E18), "█", "") | N18: =IF(AND(NOT(ISBLANK(D18)), N$10>=D18, N$10<=E18), "█", "") | O18: =IF(AND(NOT(ISBLANK(D18)), O$10>=D18, O$10<=E18), "█", "") | P18: =IF(AND(NOT(ISBLANK(D18)), P$10>=D18, P$10<=E18), "█", "") | Q18: =IF(AND(NOT(ISBLANK(D18)), Q$10>=D18, Q$10<=E18), "█", "") | R18: =IF(AND(NOT(ISBLANK(D18)), R$10>=D18, R$10<=E18), "█", "") | S18: =IF(AND(NOT(ISBLANK(D18)), S$10>=D18, S$10<=E18), "█", "") | T18: =IF(AND(NOT(ISBLANK(D18)), T$10>=D18, T$10<=E18), "█", "") | U18: =IF(AND(NOT(ISBLANK(D18)), U$10>=D18, U$10<=E18), "█", "") | V18: =IF(AND(NOT(ISBLANK(D18)), V$10>=D18, V$10<=E18), "█", "") | W18: =IF(AND(NOT(ISBLANK(D18)), W$10>=D18, W$10<=E18), "█", "") | X18: =IF(AND(NOT(ISBLANK(D18)), X$10>=D18, X$10<=E18), "█", "") | Y18: =IF(AND(NOT(ISBLANK(D18)), Y$10>=D18, Y$10<=E18), "█", "") | Z18: =IF(AND(NOT(ISBLANK(D18)), Z$10>=D18, Z$10<=E18), "█", "") | AA18: =IF(AND(NOT(ISBLANK(D18)), AA$10>=D18, AA$10<=E18), "█", "") | AB18: =IF(AND(NOT(ISBLANK(D18)), AB$10>=D18, AB$10<=E18), "█", "") | AC18: =IF(AND(NOT(ISBLANK(D18)), AC$10>=D18, AC$10<=E18), "█", "") | AD18: =IF(AND(NOT(ISBLANK(D18)), AD$10>=D18, AD$10<=E18), "█", "") | AE18: =IF(AND(NOT(ISBLANK(D18)), AE$10>=D18, AE$10<=E18), "█", "") | AF18: =IF(AND(NOT(ISBLANK(D18)), AF$10>=D18, AF$10<=E18), "█", "") | AG18: =IF(AND(NOT(ISBLANK(D18)), AG$10>=D18, AG$10<=E18), "█", "") | AH18: =IF(AND(NOT(ISBLANK(D18)), AH$10>=D18, AH$10<=E18), "█", "") | AI18: =IF(AND(NOT(ISBLANK(D18)), AI$10>=D18, AI$10<=E18), "█", "") | AJ18: =IF(AND(NOT(ISBLANK(D18)), AJ$10>=D18, AJ$10<=E18), "█", "") | AK18: =IF(AND(NOT(ISBLANK(D18)), AK$10>=D18, AK$10<=E18), "█", "") | AL18: =IF(AND(NOT(ISBLANK(D18)), AL$10>=D18, AL$10<=E18), "█", "") | AM18: =IF(AND(NOT(ISBLANK(D18)), AM$10>=D18, AM$10<=E18), "█", "")
A19: 8 | B19: Finalisasi & Pendaftaran Sidang | C19: Dewi | D19: 2026-07-14 | E19: 2026-07-15 | F19: =IF(OR(ISBLANK(D19), ISBLANK(E19)), "", E19-D19+1) | G19: 0 | H19: =IF(ISBLANK(B19), "", IF(G19=0, "Not Started", IF(G19=1, "Completed", "In Progress"))) | J19: =IF(AND(NOT(ISBLANK(D19)), J$10>=D19, J$10<=E19), "█", "") | K19: =IF(AND(NOT(ISBLANK(D19)), K$10>=D19, K$10<=E19), "█", "") | L19: =IF(AND(NOT(ISBLANK(D19)), L$10>=D19, L$10<=E19), "█", "") | M19: =IF(AND(NOT(ISBLANK(D19)), M$10>=D19, M$10<=E19), "█", "") | N19: =IF(AND(NOT(ISBLANK(D19)), N$10>=D19, N$10<=E19), "█", "") | O19: =IF(AND(NOT(ISBLANK(D19)), O$10>=D19, O$10<=E19), "█", "") | P19: =IF(AND(NOT(ISBLANK(D19)), P$10>=D19, P$10<=E19), "█", "") | Q19: =IF(AND(NOT(ISBLANK(D19)), Q$10>=D19, Q$10<=E19), "█", "") | R19: =IF(AND(NOT(ISBLANK(D19)), R$10>=D19, R$10<=E19), "█", "") | S19: =IF(AND(NOT(ISBLANK(D19)), S$10>=D19, S$10<=E19), "█", "") | T19: =IF(AND(NOT(ISBLANK(D19)), T$10>=D19, T$10<=E19), "█", "") | U19: =IF(AND(NOT(ISBLANK(D19)), U$10>=D19, U$10<=E19), "█", "") | V19: =IF(AND(NOT(ISBLANK(D19)), V$10>=D19, V$10<=E19), "█", "") | W19: =IF(AND(NOT(ISBLANK(D19)), W$10>=D19, W$10<=E19), "█", "") | X19: =IF(AND(NOT(ISBLANK(D19)), X$10>=D19, X$10<=E19), "█", "") | Y19: =IF(AND(NOT(ISBLANK(D19)), Y$10>=D19, Y$10<=E19), "█", "") | Z19: =IF(AND(NOT(ISBLANK(D19)), Z$10>=D19, Z$10<=E19), "█", "") | AA19: =IF(AND(NOT(ISBLANK(D19)), AA$10>=D19, AA$10<=E19), "█", "") | AB19: =IF(AND(NOT(ISBLANK(D19)), AB$10>=D19, AB$10<=E19), "█", "") | AC19: =IF(AND(NOT(ISBLANK(D19)), AC$10>=D19, AC$10<=E19), "█", "") | AD19: =IF(AND(NOT(ISBLANK(D19)), AD$10>=D19, AD$10<=E19), "█", "") | AE19: =IF(AND(NOT(ISBLANK(D19)), AE$10>=D19, AE$10<=E19), "█", "") | AF19: =IF(AND(NOT(ISBLANK(D19)), AF$10>=D19, AF$10<=E19), "█", "") | AG19: =IF(AND(NOT(ISBLANK(D19)), AG$10>=D19, AG$10<=E19), "█", "") | AH19: =IF(AND(NOT(ISBLANK(D19)), AH$10>=D19, AH$10<=E19), "█", "") | AI19: =IF(AND(NOT(ISBLANK(D19)), AI$10>=D19, AI$10<=E19), "█", "") | AJ19: =IF(AND(NOT(ISBLANK(D19)), AJ$10>=D19, AJ$10<=E19), "█", "") | AK19: =IF(AND(NOT(ISBLANK(D19)), AK$10>=D19, AK$10<=E19), "█", "") | AL19: =IF(AND(NOT(ISBLANK(D19)), AL$10>=D19, AL$10<=E19), "█", "") | AM19: =IF(AND(NOT(ISBLANK(D19)), AM$10>=D19, AM$10<=E19), "█", "")
A20: 9 | F20: =IF(OR(ISBLANK(D20), ISBLANK(E20)), "", E20-D20+1) | H20: =IF(ISBLANK(B20), "", IF(G20=0, "Not Started", IF(G20=1, "Completed", "In Progress"))) | J20: =IF(AND(NOT(ISBLANK(D20)), J$10>=D20, J$10<=E20), "█", "") | K20: =IF(AND(NOT(ISBLANK(D20)), K$10>=D20, K$10<=E20), "█", "") | L20: =IF(AND(NOT(ISBLANK(D20)), L$10>=D20, L$10<=E20), "█", "") | M20: =IF(AND(NOT(ISBLANK(D20)), M$10>=D20, M$10<=E20), "█", "") | N20: =IF(AND(NOT(ISBLANK(D20)), N$10>=D20, N$10<=E20), "█", "") | O20: =IF(AND(NOT(ISBLANK(D20)), O$10>=D20, O$10<=E20), "█", "") | P20: =IF(AND(NOT(ISBLANK(D20)), P$10>=D20, P$10<=E20), "█", "") | Q20: =IF(AND(NOT(ISBLANK(D20)), Q$10>=D20, Q$10<=E20), "█", "") | R20: =IF(AND(NOT(ISBLANK(D20)), R$10>=D20, R$10<=E20), "█", "") | S20: =IF(AND(NOT(ISBLANK(D20)), S$10>=D20, S$10<=E20), "█", "") | T20: =IF(AND(NOT(ISBLANK(D20)), T$10>=D20, T$10<=E20), "█", "") | U20: =IF(AND(NOT(ISBLANK(D20)), U$10>=D20, U$10<=E20), "█", "") | V20: =IF(AND(NOT(ISBLANK(D20)), V$10>=D20, V$10<=E20), "█", "") | W20: =IF(AND(NOT(ISBLANK(D20)), W$10>=D20, W$10<=E20), "█", "") | X20: =IF(AND(NOT(ISBLANK(D20)), X$10>=D20, X$10<=E20), "█", "") | Y20: =IF(AND(NOT(ISBLANK(D20)), Y$10>=D20, Y$10<=E20), "█", "") | Z20: =IF(AND(NOT(ISBLANK(D20)), Z$10>=D20, Z$10<=E20), "█", "") | AA20: =IF(AND(NOT(ISBLANK(D20)), AA$10>=D20, AA$10<=E20), "█", "") | AB20: =IF(AND(NOT(ISBLANK(D20)), AB$10>=D20, AB$10<=E20), "█", "") | AC20: =IF(AND(NOT(ISBLANK(D20)), AC$10>=D20, AC$10<=E20), "█", "") | AD20: =IF(AND(NOT(ISBLANK(D20)), AD$10>=D20, AD$10<=E20), "█", "") | AE20: =IF(AND(NOT(ISBLANK(D20)), AE$10>=D20, AE$10<=E20), "█", "") | AF20: =IF(AND(NOT(ISBLANK(D20)), AF$10>=D20, AF$10<=E20), "█", "") | AG20: =IF(AND(NOT(ISBLANK(D20)), AG$10>=D20, AG$10<=E20), "█", "") | AH20: =IF(AND(NOT(ISBLANK(D20)), AH$10>=D20, AH$10<=E20), "█", "") | AI20: =IF(AND(NOT(ISBLANK(D20)), AI$10>=D20, AI$10<=E20), "█", "") | AJ20: =IF(AND(NOT(ISBLANK(D20)), AJ$10>=D20, AJ$10<=E20), "█", "") | AK20: =IF(AND(NOT(ISBLANK(D20)), AK$10>=D20, AK$10<=E20), "█", "") | AL20: =IF(AND(NOT(ISBLANK(D20)), AL$10>=D20, AL$10<=E20), "█", "") | AM20: =IF(AND(NOT(ISBLANK(D20)), AM$10>=D20, AM$10<=E20), "█", "")
A21: 10 | F21: =IF(OR(ISBLANK(D21), ISBLANK(E21)), "", E21-D21+1) | H21: =IF(ISBLANK(B21), "", IF(G21=0, "Not Started", IF(G21=1, "Completed", "In Progress"))) | J21: =IF(AND(NOT(ISBLANK(D21)), J$10>=D21, J$10<=E21), "█", "") | K21: =IF(AND(NOT(ISBLANK(D21)), K$10>=D21, K$10<=E21), "█", "") | L21: =IF(AND(NOT(ISBLANK(D21)), L$10>=D21, L$10<=E21), "█", "") | M21: =IF(AND(NOT(ISBLANK(D21)), M$10>=D21, M$10<=E21), "█", "") | N21: =IF(AND(NOT(ISBLANK(D21)), N$10>=D21, N$10<=E21), "█", "") | O21: =IF(AND(NOT(ISBLANK(D21)), O$10>=D21, O$10<=E21), "█", "") | P21: =IF(AND(NOT(ISBLANK(D21)), P$10>=D21, P$10<=E21), "█", "") | Q21: =IF(AND(NOT(ISBLANK(D21)), Q$10>=D21, Q$10<=E21), "█", "") | R21: =IF(AND(NOT(ISBLANK(D21)), R$10>=D21, R$10<=E21), "█", "") | S21: =IF(AND(NOT(ISBLANK(D21)), S$10>=D21, S$10<=E21), "█", "") | T21: =IF(AND(NOT(ISBLANK(D21)), T$10>=D21, T$10<=E21), "█", "") | U21: =IF(AND(NOT(ISBLANK(D21)), U$10>=D21, U$10<=E21), "█", "") | V21: =IF(AND(NOT(ISBLANK(D21)), V$10>=D21, V$10<=E21), "█", "") | W21: =IF(AND(NOT(ISBLANK(D21)), W$10>=D21, W$10<=E21), "█", "") | X21: =IF(AND(NOT(ISBLANK(D21)), X$10>=D21, X$10<=E21), "█", "") | Y21: =IF(AND(NOT(ISBLANK(D21)), Y$10>=D21, Y$10<=E21), "█", "") | Z21: =IF(AND(NOT(ISBLANK(D21)), Z$10>=D21, Z$10<=E21), "█", "") | AA21: =IF(AND(NOT(ISBLANK(D21)), AA$10>=D21, AA$10<=E21), "█", "") | AB21: =IF(AND(NOT(ISBLANK(D21)), AB$10>=D21, AB$10<=E21), "█", "") | AC21: =IF(AND(NOT(ISBLANK(D21)), AC$10>=D21, AC$10<=E21), "█", "") | AD21: =IF(AND(NOT(ISBLANK(D21)), AD$10>=D21, AD$10<=E21), "█", "") | AE21: =IF(AND(NOT(ISBLANK(D21)), AE$10>=D21, AE$10<=E21), "█", "") | AF21: =IF(AND(NOT(ISBLANK(D21)), AF$10>=D21, AF$10<=E21), "█", "") | AG21: =IF(AND(NOT(ISBLANK(D21)), AG$10>=D21, AG$10<=E21), "█", "") | AH21: =IF(AND(NOT(ISBLANK(D21)), AH$10>=D21, AH$10<=E21), "█", "") | AI21: =IF(AND(NOT(ISBLANK(D21)), AI$10>=D21, AI$10<=E21), "█", "") | AJ21: =IF(AND(NOT(ISBLANK(D21)), AJ$10>=D21, AJ$10<=E21), "█", "") | AK21: =IF(AND(NOT(ISBLANK(D21)), AK$10>=D21, AK$10<=E21), "█", "") | AL21: =IF(AND(NOT(ISBLANK(D21)), AL$10>=D21, AL$10<=E21), "█", "") | AM21: =IF(AND(NOT(ISBLANK(D21)), AM$10>=D21, AM$10<=E21), "█", "")
A22: 11 | F22: =IF(OR(ISBLANK(D22), ISBLANK(E22)), "", E22-D22+1) | H22: =IF(ISBLANK(B22), "", IF(G22=0, "Not Started", IF(G22=1, "Completed", "In Progress"))) | J22: =IF(AND(NOT(ISBLANK(D22)), J$10>=D22, J$10<=E22), "█", "") | K22: =IF(AND(NOT(ISBLANK(D22)), K$10>=D22, K$10<=E22), "█", "") | L22: =IF(AND(NOT(ISBLANK(D22)), L$10>=D22, L$10<=E22), "█", "") | M22: =IF(AND(NOT(ISBLANK(D22)), M$10>=D22, M$10<=E22), "█", "") | N22: =IF(AND(NOT(ISBLANK(D22)), N$10>=D22, N$10<=E22), "█", "") | O22: =IF(AND(NOT(ISBLANK(D22)), O$10>=D22, O$10<=E22), "█", "") | P22: =IF(AND(NOT(ISBLANK(D22)), P$10>=D22, P$10<=E22), "█", "") | Q22: =IF(AND(NOT(ISBLANK(D22)), Q$10>=D22, Q$10<=E22), "█", "") | R22: =IF(AND(NOT(ISBLANK(D22)), R$10>=D22, R$10<=E22), "█", "") | S22: =IF(AND(NOT(ISBLANK(D22)), S$10>=D22, S$10<=E22), "█", "") | T22: =IF(AND(NOT(ISBLANK(D22)), T$10>=D22, T$10<=E22), "█", "") | U22: =IF(AND(NOT(ISBLANK(D22)), U$10>=D22, U$10<=E22), "█", "") | V22: =IF(AND(NOT(ISBLANK(D22)), V$10>=D22, V$10<=E22), "█", "") | W22: =IF(AND(NOT(ISBLANK(D22)), W$10>=D22, W$10<=E22), "█", "") | X22: =IF(AND(NOT(ISBLANK(D22)), X$10>=D22, X$10<=E22), "█", "") | Y22: =IF(AND(NOT(ISBLANK(D22)), Y$10>=D22, Y$10<=E22), "█", "") | Z22: =IF(AND(NOT(ISBLANK(D22)), Z$10>=D22, Z$10<=E22), "█", "") | AA22: =IF(AND(NOT(ISBLANK(D22)), AA$10>=D22, AA$10<=E22), "█", "") | AB22: =IF(AND(NOT(ISBLANK(D22)), AB$10>=D22, AB$10<=E22), "█", "") | AC22: =IF(AND(NOT(ISBLANK(D22)), AC$10>=D22, AC$10<=E22), "█", "") | AD22: =IF(AND(NOT(ISBLANK(D22)), AD$10>=D22, AD$10<=E22), "█", "") | AE22: =IF(AND(NOT(ISBLANK(D22)), AE$10>=D22, AE$10<=E22), "█", "") | AF22: =IF(AND(NOT(ISBLANK(D22)), AF$10>=D22, AF$10<=E22), "█", "") | AG22: =IF(AND(NOT(ISBLANK(D22)), AG$10>=D22, AG$10<=E22), "█", "") | AH22: =IF(AND(NOT(ISBLANK(D22)), AH$10>=D22, AH$10<=E22), "█", "") | AI22: =IF(AND(NOT(ISBLANK(D22)), AI$10>=D22, AI$10<=E22), "█", "") | AJ22: =IF(AND(NOT(ISBLANK(D22)), AJ$10>=D22, AJ$10<=E22), "█", "") | AK22: =IF(AND(NOT(ISBLANK(D22)), AK$10>=D22, AK$10<=E22), "█", "") | AL22: =IF(AND(NOT(ISBLANK(D22)), AL$10>=D22, AL$10<=E22), "█", "") | AM22: =IF(AND(NOT(ISBLANK(D22)), AM$10>=D22, AM$10<=E22), "█", "")
A23: 12 | F23: =IF(OR(ISBLANK(D23), ISBLANK(E23)), "", E23-D23+1) | H23: =IF(ISBLANK(B23), "", IF(G23=0, "Not Started", IF(G23=1, "Completed", "In Progress"))) | J23: =IF(AND(NOT(ISBLANK(D23)), J$10>=D23, J$10<=E23), "█", "") | K23: =IF(AND(NOT(ISBLANK(D23)), K$10>=D23, K$10<=E23), "█", "") | L23: =IF(AND(NOT(ISBLANK(D23)), L$10>=D23, L$10<=E23), "█", "") | M23: =IF(AND(NOT(ISBLANK(D23)), M$10>=D23, M$10<=E23), "█", "") | N23: =IF(AND(NOT(ISBLANK(D23)), N$10>=D23, N$10<=E23), "█", "") | O23: =IF(AND(NOT(ISBLANK(D23)), O$10>=D23, O$10<=E23), "█", "") | P23: =IF(AND(NOT(ISBLANK(D23)), P$10>=D23, P$10<=E23), "█", "") | Q23: =IF(AND(NOT(ISBLANK(D23)), Q$10>=D23, Q$10<=E23), "█", "") | R23: =IF(AND(NOT(ISBLANK(D23)), R$10>=D23, R$10<=E23), "█", "") | S23: =IF(AND(NOT(ISBLANK(D23)), S$10>=D23, S$10<=E23), "█", "") | T23: =IF(AND(NOT(ISBLANK(D23)), T$10>=D23, T$10<=E23), "█", "") | U23: =IF(AND(NOT(ISBLANK(D23)), U$10>=D23, U$10<=E23), "█", "") | V23: =IF(AND(NOT(ISBLANK(D23)), V$10>=D23, V$10<=E23), "█", "") | W23: =IF(AND(NOT(ISBLANK(D23)), W$10>=D23, W$10<=E23), "█", "") | X23: =IF(AND(NOT(ISBLANK(D23)), X$10>=D23, X$10<=E23), "█", "") | Y23: =IF(AND(NOT(ISBLANK(D23)), Y$10>=D23, Y$10<=E23), "█", "") | Z23: =IF(AND(NOT(ISBLANK(D23)), Z$10>=D23, Z$10<=E23), "█", "") | AA23: =IF(AND(NOT(ISBLANK(D23)), AA$10>=D23, AA$10<=E23), "█", "") | AB23: =IF(AND(NOT(ISBLANK(D23)), AB$10>=D23, AB$10<=E23), "█", "") | AC23: =IF(AND(NOT(ISBLANK(D23)), AC$10>=D23, AC$10<=E23), "█", "") | AD23: =IF(AND(NOT(ISBLANK(D23)), AD$10>=D23, AD$10<=E23), "█", "") | AE23: =IF(AND(NOT(ISBLANK(D23)), AE$10>=D23, AE$10<=E23), "█", "") | AF23: =IF(AND(NOT(ISBLANK(D23)), AF$10>=D23, AF$10<=E23), "█", "") | AG23: =IF(AND(NOT(ISBLANK(D23)), AG$10>=D23, AG$10<=E23), "█", "") | AH23: =IF(AND(NOT(ISBLANK(D23)), AH$10>=D23, AH$10<=E23), "█", "") | AI23: =IF(AND(NOT(ISBLANK(D23)), AI$10>=D23, AI$10<=E23), "█", "") | AJ23: =IF(AND(NOT(ISBLANK(D23)), AJ$10>=D23, AJ$10<=E23), "█", "") | AK23: =IF(AND(NOT(ISBLANK(D23)), AK$10>=D23, AK$10<=E23), "█", "") | AL23: =IF(AND(NOT(ISBLANK(D23)), AL$10>=D23, AL$10<=E23), "█", "") | AM23: =IF(AND(NOT(ISBLANK(D23)), AM$10>=D23, AM$10<=E23), "█", "")
A24: 13 | F24: =IF(OR(ISBLANK(D24), ISBLANK(E24)), "", E24-D24+1) | H24: =IF(ISBLANK(B24), "", IF(G24=0, "Not Started", IF(G24=1, "Completed", "In Progress"))) | J24: =IF(AND(NOT(ISBLANK(D24)), J$10>=D24, J$10<=E24), "█", "") | K24: =IF(AND(NOT(ISBLANK(D24)), K$10>=D24, K$10<=E24), "█", "") | L24: =IF(AND(NOT(ISBLANK(D24)), L$10>=D24, L$10<=E24), "█", "") | M24: =IF(AND(NOT(ISBLANK(D24)), M$10>=D24, M$10<=E24), "█", "") | N24: =IF(AND(NOT(ISBLANK(D24)), N$10>=D24, N$10<=E24), "█", "") | O24: =IF(AND(NOT(ISBLANK(D24)), O$10>=D24, O$10<=E24), "█", "") | P24: =IF(AND(NOT(ISBLANK(D24)), P$10>=D24, P$10<=E24), "█", "") | Q24: =IF(AND(NOT(ISBLANK(D24)), Q$10>=D24, Q$10<=E24), "█", "") | R24: =IF(AND(NOT(ISBLANK(D24)), R$10>=D24, R$10<=E24), "█", "") | S24: =IF(AND(NOT(ISBLANK(D24)), S$10>=D24, S$10<=E24), "█", "") | T24: =IF(AND(NOT(ISBLANK(D24)), T$10>=D24, T$10<=E24), "█", "") | U24: =IF(AND(NOT(ISBLANK(D24)), U$10>=D24, U$10<=E24), "█", "") | V24: =IF(AND(NOT(ISBLANK(D24)), V$10>=D24, V$10<=E24), "█", "") | W24: =IF(AND(NOT(ISBLANK(D24)), W$10>=D24, W$10<=E24), "█", "") | X24: =IF(AND(NOT(ISBLANK(D24)), X$10>=D24, X$10<=E24), "█", "") | Y24: =IF(AND(NOT(ISBLANK(D24)), Y$10>=D24, Y$10<=E24), "█", "") | Z24: =IF(AND(NOT(ISBLANK(D24)), Z$10>=D24, Z$10<=E24), "█", "") | AA24: =IF(AND(NOT(ISBLANK(D24)), AA$10>=D24, AA$10<=E24), "█", "") | AB24: =IF(AND(NOT(ISBLANK(D24)), AB$10>=D24, AB$10<=E24), "█", "") | AC24: =IF(AND(NOT(ISBLANK(D24)), AC$10>=D24, AC$10<=E24), "█", "") | AD24: =IF(AND(NOT(ISBLANK(D24)), AD$10>=D24, AD$10<=E24), "█", "") | AE24: =IF(AND(NOT(ISBLANK(D24)), AE$10>=D24, AE$10<=E24), "█", "") | AF24: =IF(AND(NOT(ISBLANK(D24)), AF$10>=D24, AF$10<=E24), "█", "") | AG24: =IF(AND(NOT(ISBLANK(D24)), AG$10>=D24, AG$10<=E24), "█", "") | AH24: =IF(AND(NOT(ISBLANK(D24)), AH$10>=D24, AH$10<=E24), "█", "") | AI24: =IF(AND(NOT(ISBLANK(D24)), AI$10>=D24, AI$10<=E24), "█", "") | AJ24: =IF(AND(NOT(ISBLANK(D24)), AJ$10>=D24, AJ$10<=E24), "█", "") | AK24: =IF(AND(NOT(ISBLANK(D24)), AK$10>=D24, AK$10<=E24), "█", "") | AL24: =IF(AND(NOT(ISBLANK(D24)), AL$10>=D24, AL$10<=E24), "█", "") | AM24: =IF(AND(NOT(ISBLANK(D24)), AM$10>=D24, AM$10<=E24), "█", "")
A25: 14 | F25: =IF(OR(ISBLANK(D25), ISBLANK(E25)), "", E25-D25+1) | H25: =IF(ISBLANK(B25), "", IF(G25=0, "Not Started", IF(G25=1, "Completed", "In Progress"))) | J25: =IF(AND(NOT(ISBLANK(D25)), J$10>=D25, J$10<=E25), "█", "") | K25: =IF(AND(NOT(ISBLANK(D25)), K$10>=D25, K$10<=E25), "█", "") | L25: =IF(AND(NOT(ISBLANK(D25)), L$10>=D25, L$10<=E25), "█", "") | M25: =IF(AND(NOT(ISBLANK(D25)), M$10>=D25, M$10<=E25), "█", "") | N25: =IF(AND(NOT(ISBLANK(D25)), N$10>=D25, N$10<=E25), "█", "") | O25: =IF(AND(NOT(ISBLANK(D25)), O$10>=D25, O$10<=E25), "█", "") | P25: =IF(AND(NOT(ISBLANK(D25)), P$10>=D25, P$10<=E25), "█", "") | Q25: =IF(AND(NOT(ISBLANK(D25)), Q$10>=D25, Q$10<=E25), "█", "") | R25: =IF(AND(NOT(ISBLANK(D25)), R$10>=D25, R$10<=E25), "█", "") | S25: =IF(AND(NOT(ISBLANK(D25)), S$10>=D25, S$10<=E25), "█", "") | T25: =IF(AND(NOT(ISBLANK(D25)), T$10>=D25, T$10<=E25), "█", "") | U25: =IF(AND(NOT(ISBLANK(D25)), U$10>=D25, U$10<=E25), "█", "") | V25: =IF(AND(NOT(ISBLANK(D25)), V$10>=D25, V$10<=E25), "█", "") | W25: =IF(AND(NOT(ISBLANK(D25)), W$10>=D25, W$10<=E25), "█", "") | X25: =IF(AND(NOT(ISBLANK(D25)), X$10>=D25, X$10<=E25), "█", "") | Y25: =IF(AND(NOT(ISBLANK(D25)), Y$10>=D25, Y$10<=E25), "█", "") | Z25: =IF(AND(NOT(ISBLANK(D25)), Z$10>=D25, Z$10<=E25), "█", "") | AA25: =IF(AND(NOT(ISBLANK(D25)), AA$10>=D25, AA$10<=E25), "█", "") | AB25: =IF(AND(NOT(ISBLANK(D25)), AB$10>=D25, AB$10<=E25), "█", "") | AC25: =IF(AND(NOT(ISBLANK(D25)), AC$10>=D25, AC$10<=E25), "█", "") | AD25: =IF(AND(NOT(ISBLANK(D25)), AD$10>=D25, AD$10<=E25), "█", "") | AE25: =IF(AND(NOT(ISBLANK(D25)), AE$10>=D25, AE$10<=E25), "█", "") | AF25: =IF(AND(NOT(ISBLANK(D25)), AF$10>=D25, AF$10<=E25), "█", "") | AG25: =IF(AND(NOT(ISBLANK(D25)), AG$10>=D25, AG$10<=E25), "█", "") | AH25: =IF(AND(NOT(ISBLANK(D25)), AH$10>=D25, AH$10<=E25), "█", "") | AI25: =IF(AND(NOT(ISBLANK(D25)), AI$10>=D25, AI$10<=E25), "█", "") | AJ25: =IF(AND(NOT(ISBLANK(D25)), AJ$10>=D25, AJ$10<=E25), "█", "") | AK25: =IF(AND(NOT(ISBLANK(D25)), AK$10>=D25, AK$10<=E25), "█", "") | AL25: =IF(AND(NOT(ISBLANK(D25)), AL$10>=D25, AL$10<=E25), "█", "") | AM25: =IF(AND(NOT(ISBLANK(D25)), AM$10>=D25, AM$10<=E25), "█", "")
A26: 15 | F26: =IF(OR(ISBLANK(D26), ISBLANK(E26)), "", E26-D26+1) | H26: =IF(ISBLANK(B26), "", IF(G26=0, "Not Started", IF(G26=1, "Completed", "In Progress"))) | J26: =IF(AND(NOT(ISBLANK(D26)), J$10>=D26, J$10<=E26), "█", "") | K26: =IF(AND(NOT(ISBLANK(D26)), K$10>=D26, K$10<=E26), "█", "") | L26: =IF(AND(NOT(ISBLANK(D26)), L$10>=D26, L$10<=E26), "█", "") | M26: =IF(AND(NOT(ISBLANK(D26)), M$10>=D26, M$10<=E26), "█", "") | N26: =IF(AND(NOT(ISBLANK(D26)), N$10>=D26, N$10<=E26), "█", "") | O26: =IF(AND(NOT(ISBLANK(D26)), O$10>=D26, O$10<=E26), "█", "") | P26: =IF(AND(NOT(ISBLANK(D26)), P$10>=D26, P$10<=E26), "█", "") | Q26: =IF(AND(NOT(ISBLANK(D26)), Q$10>=D26, Q$10<=E26), "█", "") | R26: =IF(AND(NOT(ISBLANK(D26)), R$10>=D26, R$10<=E26), "█", "") | S26: =IF(AND(NOT(ISBLANK(D26)), S$10>=D26, S$10<=E26), "█", "") | T26: =IF(AND(NOT(ISBLANK(D26)), T$10>=D26, T$10<=E26), "█", "") | U26: =IF(AND(NOT(ISBLANK(D26)), U$10>=D26, U$10<=E26), "█", "") | V26: =IF(AND(NOT(ISBLANK(D26)), V$10>=D26, V$10<=E26), "█", "") | W26: =IF(AND(NOT(ISBLANK(D26)), W$10>=D26, W$10<=E26), "█", "") | X26: =IF(AND(NOT(ISBLANK(D26)), X$10>=D26, X$10<=E26), "█", "") | Y26: =IF(AND(NOT(ISBLANK(D26)), Y$10>=D26, Y$10<=E26), "█", "") | Z26: =IF(AND(NOT(ISBLANK(D26)), Z$10>=D26, Z$10<=E26), "█", "") | AA26: =IF(AND(NOT(ISBLANK(D26)), AA$10>=D26, AA$10<=E26), "█", "") | AB26: =IF(AND(NOT(ISBLANK(D26)), AB$10>=D26, AB$10<=E26), "█", "") | AC26: =IF(AND(NOT(ISBLANK(D26)), AC$10>=D26, AC$10<=E26), "█", "") | AD26: =IF(AND(NOT(ISBLANK(D26)), AD$10>=D26, AD$10<=E26), "█", "") | AE26: =IF(AND(NOT(ISBLANK(D26)), AE$10>=D26, AE$10<=E26), "█", "") | AF26: =IF(AND(NOT(ISBLANK(D26)), AF$10>=D26, AF$10<=E26), "█", "") | AG26: =IF(AND(NOT(ISBLANK(D26)), AG$10>=D26, AG$10<=E26), "█", "") | AH26: =IF(AND(NOT(ISBLANK(D26)), AH$10>=D26, AH$10<=E26), "█", "") | AI26: =IF(AND(NOT(ISBLANK(D26)), AI$10>=D26, AI$10<=E26), "█", "") | AJ26: =IF(AND(NOT(ISBLANK(D26)), AJ$10>=D26, AJ$10<=E26), "█", "") | AK26: =IF(AND(NOT(ISBLANK(D26)), AK$10>=D26, AK$10<=E26), "█", "") | AL26: =IF(AND(NOT(ISBLANK(D26)), AL$10>=D26, AL$10<=E26), "█", "") | AM26: =IF(AND(NOT(ISBLANK(D26)), AM$10>=D26, AM$10<=E26), "█", "")
F27: =IF(OR(ISBLANK(D27), ISBLANK(E27)), "", E27-D27+1) | H27: =IF(ISBLANK(B27), "", IF(G27=0, "Not Started", IF(G27=1, "Completed", "In Progress"))) | J27: =IF(AND(NOT(ISBLANK(D27)), J$10>=D27, J$10<=E27), "█", "") | K27: =IF(AND(NOT(ISBLANK(D27)), K$10>=D27, K$10<=E27), "█", "") | L27: =IF(AND(NOT(ISBLANK(D27)), L$10>=D27, L$10<=E27), "█", "") | M27: =IF(AND(NOT(ISBLANK(D27)), M$10>=D27, M$10<=E27), "█", "") | N27: =IF(AND(NOT(ISBLANK(D27)), N$10>=D27, N$10<=E27), "█", "") | O27: =IF(AND(NOT(ISBLANK(D27)), O$10>=D27, O$10<=E27), "█", "") | P27: =IF(AND(NOT(ISBLANK(D27)), P$10>=D27, P$10<=E27), "█", "") | Q27: =IF(AND(NOT(ISBLANK(D27)), Q$10>=D27, Q$10<=E27), "█", "") | R27: =IF(AND(NOT(ISBLANK(D27)), R$10>=D27, R$10<=E27), "█", "") | S27: =IF(AND(NOT(ISBLANK(D27)), S$10>=D27, S$10<=E27), "█", "") | T27: =IF(AND(NOT(ISBLANK(D27)), T$10>=D27, T$10<=E27), "█", "") | U27: =IF(AND(NOT(ISBLANK(D27)), U$10>=D27, U$10<=E27), "█", "") | V27: =IF(AND(NOT(ISBLANK(D27)), V$10>=D27, V$10<=E27), "█", "") | W27: =IF(AND(NOT(ISBLANK(D27)), W$10>=D27, W$10<=E27), "█", "") | X27: =IF(AND(NOT(ISBLANK(D27)), X$10>=D27, X$10<=E27), "█", "") | Y27: =IF(AND(NOT(ISBLANK(D27)), Y$10>=D27, Y$10<=E27), "█", "") | Z27: =IF(AND(NOT(ISBLANK(D27)), Z$10>=D27, Z$10<=E27), "█", "") | AA27: =IF(AND(NOT(ISBLANK(D27)), AA$10>=D27, AA$10<=E27), "█", "") | AB27: =IF(AND(NOT(ISBLANK(D27)), AB$10>=D27, AB$10<=E27), "█", "") | AC27: =IF(AND(NOT(ISBLANK(D27)), AC$10>=D27, AC$10<=E27), "█", "") | AD27: =IF(AND(NOT(ISBLANK(D27)), AD$10>=D27, AD$10<=E27), "█", "") | AE27: =IF(AND(NOT(ISBLANK(D27)), AE$10>=D27, AE$10<=E27), "█", "") | AF27: =IF(AND(NOT(ISBLANK(D27)), AF$10>=D27, AF$10<=E27), "█", "") | AG27: =IF(AND(NOT(ISBLANK(D27)), AG$10>=D27, AG$10<=E27), "█", "") | AH27: =IF(AND(NOT(ISBLANK(D27)), AH$10>=D27, AH$10<=E27), "█", "") | AI27: =IF(AND(NOT(ISBLANK(D27)), AI$10>=D27, AI$10<=E27), "█", "") | AJ27: =IF(AND(NOT(ISBLANK(D27)), AJ$10>=D27, AJ$10<=E27), "█", "") | AK27: =IF(AND(NOT(ISBLANK(D27)), AK$10>=D27, AK$10<=E27), "█", "") | AL27: =IF(AND(NOT(ISBLANK(D27)), AL$10>=D27, AL$10<=E27), "█", "") | AM27: =IF(AND(NOT(ISBLANK(D27)), AM$10>=D27, AM$10<=E27), "█", "")
F28: =IF(OR(ISBLANK(D28), ISBLANK(E28)), "", E28-D28+1) | H28: =IF(ISBLANK(B28), "", IF(G28=0, "Not Started", IF(G28=1, "Completed", "In Progress"))) | J28: =IF(AND(NOT(ISBLANK(D28)), J$10>=D28, J$10<=E28), "█", "") | K28: =IF(AND(NOT(ISBLANK(D28)), K$10>=D28, K$10<=E28), "█", "") | L28: =IF(AND(NOT(ISBLANK(D28)), L$10>=D28, L$10<=E28), "█", "") | M28: =IF(AND(NOT(ISBLANK(D28)), M$10>=D28, M$10<=E28), "█", "") | N28: =IF(AND(NOT(ISBLANK(D28)), N$10>=D28, N$10<=E28), "█", "") | O28: =IF(AND(NOT(ISBLANK(D28)), O$10>=D28, O$10<=E28), "█", "") | P28: =IF(AND(NOT(ISBLANK(D28)), P$10>=D28, P$10<=E28), "█", "") | Q28: =IF(AND(NOT(ISBLANK(D28)), Q$10>=D28, Q$10<=E28), "█", "") | R28: =IF(AND(NOT(ISBLANK(D28)), R$10>=D28, R$10<=E28), "█", "") | S28: =IF(AND(NOT(ISBLANK(D28)), S$10>=D28, S$10<=E28), "█", "") | T28: =IF(AND(NOT(ISBLANK(D28)), T$10>=D28, T$10<=E28), "█", "") | U28: =IF(AND(NOT(ISBLANK(D28)), U$10>=D28, U$10<=E28), "█", "") | V28: =IF(AND(NOT(ISBLANK(D28)), V$10>=D28, V$10<=E28), "█", "") | W28: =IF(AND(NOT(ISBLANK(D28)), W$10>=D28, W$10<=E28), "█", "") | X28: =IF(AND(NOT(ISBLANK(D28)), X$10>=D28, X$10<=E28), "█", "") | Y28: =IF(AND(NOT(ISBLANK(D28)), Y$10>=D28, Y$10<=E28), "█", "") | Z28: =IF(AND(NOT(ISBLANK(D28)), Z$10>=D28, Z$10<=E28), "█", "") | AA28: =IF(AND(NOT(ISBLANK(D28)), AA$10>=D28, AA$10<=E28), "█", "") | AB28: =IF(AND(NOT(ISBLANK(D28)), AB$10>=D28, AB$10<=E28), "█", "") | AC28: =IF(AND(NOT(ISBLANK(D28)), AC$10>=D28, AC$10<=E28), "█", "") | AD28: =IF(AND(NOT(ISBLANK(D28)), AD$10>=D28, AD$10<=E28), "█", "") | AE28: =IF(AND(NOT(ISBLANK(D28)), AE$10>=D28, AE$10<=E28), "█", "") | AF28: =IF(AND(NOT(ISBLANK(D28)), AF$10>=D28, AF$10<=E28), "█", "") | AG28: =IF(AND(NOT(ISBLANK(D28)), AG$10>=D28, AG$10<=E28), "█", "") | AH28: =IF(AND(NOT(ISBLANK(D28)), AH$10>=D28, AH$10<=E28), "█", "") | AI28: =IF(AND(NOT(ISBLANK(D28)), AI$10>=D28, AI$10<=E28), "█", "") | AJ28: =IF(AND(NOT(ISBLANK(D28)), AJ$10>=D28, AJ$10<=E28), "█", "") | AK28: =IF(AND(NOT(ISBLANK(D28)), AK$10>=D28, AK$10<=E28), "█", "") | AL28: =IF(AND(NOT(ISBLANK(D28)), AL$10>=D28, AL$10<=E28), "█", "") | AM28: =IF(AND(NOT(ISBLANK(D28)), AM$10>=D28, AM$10<=E28), "█", "")
F29: =IF(OR(ISBLANK(D29), ISBLANK(E29)), "", E29-D29+1) | H29: =IF(ISBLANK(B29), "", IF(G29=0, "Not Started", IF(G29=1, "Completed", "In Progress"))) | J29: =IF(AND(NOT(ISBLANK(D29)), J$10>=D29, J$10<=E29), "█", "") | K29: =IF(AND(NOT(ISBLANK(D29)), K$10>=D29, K$10<=E29), "█", "") | L29: =IF(AND(NOT(ISBLANK(D29)), L$10>=D29, L$10<=E29), "█", "") | M29: =IF(AND(NOT(ISBLANK(D29)), M$10>=D29, M$10<=E29), "█", "") | N29: =IF(AND(NOT(ISBLANK(D29)), N$10>=D29, N$10<=E29), "█", "") | O29: =IF(AND(NOT(ISBLANK(D29)), O$10>=D29, O$10<=E29), "█", "") | P29: =IF(AND(NOT(ISBLANK(D29)), P$10>=D29, P$10<=E29), "█", "") | Q29: =IF(AND(NOT(ISBLANK(D29)), Q$10>=D29, Q$10<=E29), "█", "") | R29: =IF(AND(NOT(ISBLANK(D29)), R$10>=D29, R$10<=E29), "█", "") | S29: =IF(AND(NOT(ISBLANK(D29)), S$10>=D29, S$10<=E29), "█", "") | T29: =IF(AND(NOT(ISBLANK(D29)), T$10>=D29, T$10<=E29), "█", "") | U29: =IF(AND(NOT(ISBLANK(D29)), U$10>=D29, U$10<=E29), "█", "") | V29: =IF(AND(NOT(ISBLANK(D29)), V$10>=D29, V$10<=E29), "█", "") | W29: =IF(AND(NOT(ISBLANK(D29)), W$10>=D29, W$10<=E29), "█", "") | X29: =IF(AND(NOT(ISBLANK(D29)), X$10>=D29, X$10<=E29), "█", "") | Y29: =IF(AND(NOT(ISBLANK(D29)), Y$10>=D29, Y$10<=E29), "█", "") | Z29: =IF(AND(NOT(ISBLANK(D29)), Z$10>=D29, Z$10<=E29), "█", "") | AA29: =IF(AND(NOT(ISBLANK(D29)), AA$10>=D29, AA$10<=E29), "█", "") | AB29: =IF(AND(NOT(ISBLANK(D29)), AB$10>=D29, AB$10<=E29), "█", "") | AC29: =IF(AND(NOT(ISBLANK(D29)), AC$10>=D29, AC$10<=E29), "█", "") | AD29: =IF(AND(NOT(ISBLANK(D29)), AD$10>=D29, AD$10<=E29), "█", "") | AE29: =IF(AND(NOT(ISBLANK(D29)), AE$10>=D29, AE$10<=E29), "█", "") | AF29: =IF(AND(NOT(ISBLANK(D29)), AF$10>=D29, AF$10<=E29), "█", "") | AG29: =IF(AND(NOT(ISBLANK(D29)), AG$10>=D29, AG$10<=E29), "█", "") | AH29: =IF(AND(NOT(ISBLANK(D29)), AH$10>=D29, AH$10<=E29), "█", "") | AI29: =IF(AND(NOT(ISBLANK(D29)), AI$10>=D29, AI$10<=E29), "█", "") | AJ29: =IF(AND(NOT(ISBLANK(D29)), AJ$10>=D29, AJ$10<=E29), "█", "") | AK29: =IF(AND(NOT(ISBLANK(D29)), AK$10>=D29, AK$10<=E29), "█", "") | AL29: =IF(AND(NOT(ISBLANK(D29)), AL$10>=D29, AL$10<=E29), "█", "") | AM29: =IF(AND(NOT(ISBLANK(D29)), AM$10>=D29, AM$10<=E29), "█", "")
F30: =IF(OR(ISBLANK(D30), ISBLANK(E30)), "", E30-D30+1) | H30: =IF(ISBLANK(B30), "", IF(G30=0, "Not Started", IF(G30=1, "Completed", "In Progress"))) | J30: =IF(AND(NOT(ISBLANK(D30)), J$10>=D30, J$10<=E30), "█", "") | K30: =IF(AND(NOT(ISBLANK(D30)), K$10>=D30, K$10<=E30), "█", "") | L30: =IF(AND(NOT(ISBLANK(D30)), L$10>=D30, L$10<=E30), "█", "") | M30: =IF(AND(NOT(ISBLANK(D30)), M$10>=D30, M$10<=E30), "█", "") | N30: =IF(AND(NOT(ISBLANK(D30)), N$10>=D30, N$10<=E30), "█", "") | O30: =IF(AND(NOT(ISBLANK(D30)), O$10>=D30, O$10<=E30), "█", "") | P30: =IF(AND(NOT(ISBLANK(D30)), P$10>=D30, P$10<=E30), "█", "") | Q30: =IF(AND(NOT(ISBLANK(D30)), Q$10>=D30, Q$10<=E30), "█", "") | R30: =IF(AND(NOT(ISBLANK(D30)), R$10>=D30, R$10<=E30), "█", "") | S30: =IF(AND(NOT(ISBLANK(D30)), S$10>=D30, S$10<=E30), "█", "") | T30: =IF(AND(NOT(ISBLANK(D30)), T$10>=D30, T$10<=E30), "█", "") | U30: =IF(AND(NOT(ISBLANK(D30)), U$10>=D30, U$10<=E30), "█", "") | V30: =IF(AND(NOT(ISBLANK(D30)), V$10>=D30, V$10<=E30), "█", "") | W30: =IF(AND(NOT(ISBLANK(D30)), W$10>=D30, W$10<=E30), "█", "") | X30: =IF(AND(NOT(ISBLANK(D30)), X$10>=D30, X$10<=E30), "█", "") | Y30: =IF(AND(NOT(ISBLANK(D30)), Y$10>=D30, Y$10<=E30), "█", "") | Z30: =IF(AND(NOT(ISBLANK(D30)), Z$10>=D30, Z$10<=E30), "█", "") | AA30: =IF(AND(NOT(ISBLANK(D30)), AA$10>=D30, AA$10<=E30), "█", "") | AB30: =IF(AND(NOT(ISBLANK(D30)), AB$10>=D30, AB$10<=E30), "█", "") | AC30: =IF(AND(NOT(ISBLANK(D30)), AC$10>=D30, AC$10<=E30), "█", "") | AD30: =IF(AND(NOT(ISBLANK(D30)), AD$10>=D30, AD$10<=E30), "█", "") | AE30: =IF(AND(NOT(ISBLANK(D30)), AE$10>=D30, AE$10<=E30), "█", "") | AF30: =IF(AND(NOT(ISBLANK(D30)), AF$10>=D30, AF$10<=E30), "█", "") | AG30: =IF(AND(NOT(ISBLANK(D30)), AG$10>=D30, AG$10<=E30), "█", "") | AH30: =IF(AND(NOT(ISBLANK(D30)), AH$10>=D30, AH$10<=E30), "█", "") | AI30: =IF(AND(NOT(ISBLANK(D30)), AI$10>=D30, AI$10<=E30), "█", "") | AJ30: =IF(AND(NOT(ISBLANK(D30)), AJ$10>=D30, AJ$10<=E30), "█", "") | AK30: =IF(AND(NOT(ISBLANK(D30)), AK$10>=D30, AK$10<=E30), "█", "") | AL30: =IF(AND(NOT(ISBLANK(D30)), AL$10>=D30, AL$10<=E30), "█", "") | AM30: =IF(AND(NOT(ISBLANK(D30)), AM$10>=D30, AM$10<=E30), "█", "")
F31: =IF(OR(ISBLANK(D31), ISBLANK(E31)), "", E31-D31+1) | H31: =IF(ISBLANK(B31), "", IF(G31=0, "Not Started", IF(G31=1, "Completed", "In Progress"))) | J31: =IF(AND(NOT(ISBLANK(D31)), J$10>=D31, J$10<=E31), "█", "") | K31: =IF(AND(NOT(ISBLANK(D31)), K$10>=D31, K$10<=E31), "█", "") | L31: =IF(AND(NOT(ISBLANK(D31)), L$10>=D31, L$10<=E31), "█", "") | M31: =IF(AND(NOT(ISBLANK(D31)), M$10>=D31, M$10<=E31), "█", "") | N31: =IF(AND(NOT(ISBLANK(D31)), N$10>=D31, N$10<=E31), "█", "") | O31: =IF(AND(NOT(ISBLANK(D31)), O$10>=D31, O$10<=E31), "█", "") | P31: =IF(AND(NOT(ISBLANK(D31)), P$10>=D31, P$10<=E31), "█", "") | Q31: =IF(AND(NOT(ISBLANK(D31)), Q$10>=D31, Q$10<=E31), "█", "") | R31: =IF(AND(NOT(ISBLANK(D31)), R$10>=D31, R$10<=E31), "█", "") | S31: =IF(AND(NOT(ISBLANK(D31)), S$10>=D31, S$10<=E31), "█", "") | T31: =IF(AND(NOT(ISBLANK(D31)), T$10>=D31, T$10<=E31), "█", "") | U31: =IF(AND(NOT(ISBLANK(D31)), U$10>=D31, U$10<=E31), "█", "") | V31: =IF(AND(NOT(ISBLANK(D31)), V$10>=D31, V$10<=E31), "█", "") | W31: =IF(AND(NOT(ISBLANK(D31)), W$10>=D31, W$10<=E31), "█", "") | X31: =IF(AND(NOT(ISBLANK(D31)), X$10>=D31, X$10<=E31), "█", "") | Y31: =IF(AND(NOT(ISBLANK(D31)), Y$10>=D31, Y$10<=E31), "█", "") | Z31: =IF(AND(NOT(ISBLANK(D31)), Z$10>=D31, Z$10<=E31), "█", "") | AA31: =IF(AND(NOT(ISBLANK(D31)), AA$10>=D31, AA$10<=E31), "█", "") | AB31: =IF(AND(NOT(ISBLANK(D31)), AB$10>=D31, AB$10<=E31), "█", "") | AC31: =IF(AND(NOT(ISBLANK(D31)), AC$10>=D31, AC$10<=E31), "█", "") | AD31: =IF(AND(NOT(ISBLANK(D31)), AD$10>=D31, AD$10<=E31), "█", "") | AE31: =IF(AND(NOT(ISBLANK(D31)), AE$10>=D31, AE$10<=E31), "█", "") | AF31: =IF(AND(NOT(ISBLANK(D31)), AF$10>=D31, AF$10<=E31), "█", "") | AG31: =IF(AND(NOT(ISBLANK(D31)), AG$10>=D31, AG$10<=E31), "█", "") | AH31: =IF(AND(NOT(ISBLANK(D31)), AH$10>=D31, AH$10<=E31), "█", "") | AI31: =IF(AND(NOT(ISBLANK(D31)), AI$10>=D31, AI$10<=E31), "█", "") | AJ31: =IF(AND(NOT(ISBLANK(D31)), AJ$10>=D31, AJ$10<=E31), "█", "") | AK31: =IF(AND(NOT(ISBLANK(D31)), AK$10>=D31, AK$10<=E31), "█", "") | AL31: =IF(AND(NOT(ISBLANK(D31)), AL$10>=D31, AL$10<=E31), "█", "") | AM31: =IF(AND(NOT(ISBLANK(D31)), AM$10>=D31, AM$10<=E31), "█", "")
F32: =IF(OR(ISBLANK(D32), ISBLANK(E32)), "", E32-D32+1) | H32: =IF(ISBLANK(B32), "", IF(G32=0, "Not Started", IF(G32=1, "Completed", "In Progress"))) | J32: =IF(AND(NOT(ISBLANK(D32)), J$10>=D32, J$10<=E32), "█", "") | K32: =IF(AND(NOT(ISBLANK(D32)), K$10>=D32, K$10<=E32), "█", "") | L32: =IF(AND(NOT(ISBLANK(D32)), L$10>=D32, L$10<=E32), "█", "") | M32: =IF(AND(NOT(ISBLANK(D32)), M$10>=D32, M$10<=E32), "█", "") | N32: =IF(AND(NOT(ISBLANK(D32)), N$10>=D32, N$10<=E32), "█", "") | O32: =IF(AND(NOT(ISBLANK(D32)), O$10>=D32, O$10<=E32), "█", "") | P32: =IF(AND(NOT(ISBLANK(D32)), P$10>=D32, P$10<=E32), "█", "") | Q32: =IF(AND(NOT(ISBLANK(D32)), Q$10>=D32, Q$10<=E32), "█", "") | R32: =IF(AND(NOT(ISBLANK(D32)), R$10>=D32, R$10<=E32), "█", "") | S32: =IF(AND(NOT(ISBLANK(D32)), S$10>=D32, S$10<=E32), "█", "") | T32: =IF(AND(NOT(ISBLANK(D32)), T$10>=D32, T$10<=E32), "█", "") | U32: =IF(AND(NOT(ISBLANK(D32)), U$10>=D32, U$10<=E32), "█", "") | V32: =IF(AND(NOT(ISBLANK(D32)), V$10>=D32, V$10<=E32), "█", "") | W32: =IF(AND(NOT(ISBLANK(D32)), W$10>=D32, W$10<=E32), "█", "") | X32: =IF(AND(NOT(ISBLANK(D32)), X$10>=D32, X$10<=E32), "█", "") | Y32: =IF(AND(NOT(ISBLANK(D32)), Y$10>=D32, Y$10<=E32), "█", "") | Z32: =IF(AND(NOT(ISBLANK(D32)), Z$10>=D32, Z$10<=E32), "█", "") | AA32: =IF(AND(NOT(ISBLANK(D32)), AA$10>=D32, AA$10<=E32), "█", "") | AB32: =IF(AND(NOT(ISBLANK(D32)), AB$10>=D32, AB$10<=E32), "█", "") | AC32: =IF(AND(NOT(ISBLANK(D32)), AC$10>=D32, AC$10<=E32), "█", "") | AD32: =IF(AND(NOT(ISBLANK(D32)), AD$10>=D32, AD$10<=E32), "█", "") | AE32: =IF(AND(NOT(ISBLANK(D32)), AE$10>=D32, AE$10<=E32), "█", "") | AF32: =IF(AND(NOT(ISBLANK(D32)), AF$10>=D32, AF$10<=E32), "█", "") | AG32: =IF(AND(NOT(ISBLANK(D32)), AG$10>=D32, AG$10<=E32), "█", "") | AH32: =IF(AND(NOT(ISBLANK(D32)), AH$10>=D32, AH$10<=E32), "█", "") | AI32: =IF(AND(NOT(ISBLANK(D32)), AI$10>=D32, AI$10<=E32), "█", "") | AJ32: =IF(AND(NOT(ISBLANK(D32)), AJ$10>=D32, AJ$10<=E32), "█", "") | AK32: =IF(AND(NOT(ISBLANK(D32)), AK$10>=D32, AK$10<=E32), "█", "") | AL32: =IF(AND(NOT(ISBLANK(D32)), AL$10>=D32, AL$10<=E32), "█", "") | AM32: =IF(AND(NOT(ISBLANK(D32)), AM$10>=D32, AM$10<=E32), "█", "")
F33: =IF(OR(ISBLANK(D33), ISBLANK(E33)), "", E33-D33+1) | H33: =IF(ISBLANK(B33), "", IF(G33=0, "Not Started", IF(G33=1, "Completed", "In Progress"))) | J33: =IF(AND(NOT(ISBLANK(D33)), J$10>=D33, J$10<=E33), "█", "") | K33: =IF(AND(NOT(ISBLANK(D33)), K$10>=D33, K$10<=E33), "█", "") | L33: =IF(AND(NOT(ISBLANK(D33)), L$10>=D33, L$10<=E33), "█", "") | M33: =IF(AND(NOT(ISBLANK(D33)), M$10>=D33, M$10<=E33), "█", "") | N33: =IF(AND(NOT(ISBLANK(D33)), N$10>=D33, N$10<=E33), "█", "") | O33: =IF(AND(NOT(ISBLANK(D33)), O$10>=D33, O$10<=E33), "█", "") | P33: =IF(AND(NOT(ISBLANK(D33)), P$10>=D33, P$10<=E33), "█", "") | Q33: =IF(AND(NOT(ISBLANK(D33)), Q$10>=D33, Q$10<=E33), "█", "") | R33: =IF(AND(NOT(ISBLANK(D33)), R$10>=D33, R$10<=E33), "█", "") | S33: =IF(AND(NOT(ISBLANK(D33)), S$10>=D33, S$10<=E33), "█", "") | T33: =IF(AND(NOT(ISBLANK(D33)), T$10>=D33, T$10<=E33), "█", "") | U33: =IF(AND(NOT(ISBLANK(D33)), U$10>=D33, U$10<=E33), "█", "") | V33: =IF(AND(NOT(ISBLANK(D33)), V$10>=D33, V$10<=E33), "█", "") | W33: =IF(AND(NOT(ISBLANK(D33)), W$10>=D33, W$10<=E33), "█", "") | X33: =IF(AND(NOT(ISBLANK(D33)), X$10>=D33, X$10<=E33), "█", "") | Y33: =IF(AND(NOT(ISBLANK(D33)), Y$10>=D33, Y$10<=E33), "█", "") | Z33: =IF(AND(NOT(ISBLANK(D33)), Z$10>=D33, Z$10<=E33), "█", "") | AA33: =IF(AND(NOT(ISBLANK(D33)), AA$10>=D33, AA$10<=E33), "█", "") | AB33: =IF(AND(NOT(ISBLANK(D33)), AB$10>=D33, AB$10<=E33), "█", "") | AC33: =IF(AND(NOT(ISBLANK(D33)), AC$10>=D33, AC$10<=E33), "█", "") | AD33: =IF(AND(NOT(ISBLANK(D33)), AD$10>=D33, AD$10<=E33), "█", "") | AE33: =IF(AND(NOT(ISBLANK(D33)), AE$10>=D33, AE$10<=E33), "█", "") | AF33: =IF(AND(NOT(ISBLANK(D33)), AF$10>=D33, AF$10<=E33), "█", "") | AG33: =IF(AND(NOT(ISBLANK(D33)), AG$10>=D33, AG$10<=E33), "█", "") | AH33: =IF(AND(NOT(ISBLANK(D33)), AH$10>=D33, AH$10<=E33), "█", "") | AI33: =IF(AND(NOT(ISBLANK(D33)), AI$10>=D33, AI$10<=E33), "█", "") | AJ33: =IF(AND(NOT(ISBLANK(D33)), AJ$10>=D33, AJ$10<=E33), "█", "") | AK33: =IF(AND(NOT(ISBLANK(D33)), AK$10>=D33, AK$10<=E33), "█", "") | AL33: =IF(AND(NOT(ISBLANK(D33)), AL$10>=D33, AL$10<=E33), "█", "") | AM33: =IF(AND(NOT(ISBLANK(D33)), AM$10>=D33, AM$10<=E33), "█", "")
F34: =IF(OR(ISBLANK(D34), ISBLANK(E34)), "", E34-D34+1) | H34: =IF(ISBLANK(B34), "", IF(G34=0, "Not Started", IF(G34=1, "Completed", "In Progress"))) | J34: =IF(AND(NOT(ISBLANK(D34)), J$10>=D34, J$10<=E34), "█", "") | K34: =IF(AND(NOT(ISBLANK(D34)), K$10>=D34, K$10<=E34), "█", "") | L34: =IF(AND(NOT(ISBLANK(D34)), L$10>=D34, L$10<=E34), "█", "") | M34: =IF(AND(NOT(ISBLANK(D34)), M$10>=D34, M$10<=E34), "█", "") | N34: =IF(AND(NOT(ISBLANK(D34)), N$10>=D34, N$10<=E34), "█", "") | O34: =IF(AND(NOT(ISBLANK(D34)), O$10>=D34, O$10<=E34), "█", "") | P34: =IF(AND(NOT(ISBLANK(D34)), P$10>=D34, P$10<=E34), "█", "") | Q34: =IF(AND(NOT(ISBLANK(D34)), Q$10>=D34, Q$10<=E34), "█", "") | R34: =IF(AND(NOT(ISBLANK(D34)), R$10>=D34, R$10<=E34), "█", "") | S34: =IF(AND(NOT(ISBLANK(D34)), S$10>=D34, S$10<=E34), "█", "") | T34: =IF(AND(NOT(ISBLANK(D34)), T$10>=D34, T$10<=E34), "█", "") | U34: =IF(AND(NOT(ISBLANK(D34)), U$10>=D34, U$10<=E34), "█", "") | V34: =IF(AND(NOT(ISBLANK(D34)), V$10>=D34, V$10<=E34), "█", "") | W34: =IF(AND(NOT(ISBLANK(D34)), W$10>=D34, W$10<=E34), "█", "") | X34: =IF(AND(NOT(ISBLANK(D34)), X$10>=D34, X$10<=E34), "█", "") | Y34: =IF(AND(NOT(ISBLANK(D34)), Y$10>=D34, Y$10<=E34), "█", "") | Z34: =IF(AND(NOT(ISBLANK(D34)), Z$10>=D34, Z$10<=E34), "█", "") | AA34: =IF(AND(NOT(ISBLANK(D34)), AA$10>=D34, AA$10<=E34), "█", "") | AB34: =IF(AND(NOT(ISBLANK(D34)), AB$10>=D34, AB$10<=E34), "█", "") | AC34: =IF(AND(NOT(ISBLANK(D34)), AC$10>=D34, AC$10<=E34), "█", "") | AD34: =IF(AND(NOT(ISBLANK(D34)), AD$10>=D34, AD$10<=E34), "█", "") | AE34: =IF(AND(NOT(ISBLANK(D34)), AE$10>=D34, AE$10<=E34), "█", "") | AF34: =IF(AND(NOT(ISBLANK(D34)), AF$10>=D34, AF$10<=E34), "█", "") | AG34: =IF(AND(NOT(ISBLANK(D34)), AG$10>=D34, AG$10<=E34), "█", "") | AH34: =IF(AND(NOT(ISBLANK(D34)), AH$10>=D34, AH$10<=E34), "█", "") | AI34: =IF(AND(NOT(ISBLANK(D34)), AI$10>=D34, AI$10<=E34), "█", "") | AJ34: =IF(AND(NOT(ISBLANK(D34)), AJ$10>=D34, AJ$10<=E34), "█", "") | AK34: =IF(AND(NOT(ISBLANK(D34)), AK$10>=D34, AK$10<=E34), "█", "") | AL34: =IF(AND(NOT(ISBLANK(D34)), AL$10>=D34, AL$10<=E34), "█", "") | AM34: =IF(AND(NOT(ISBLANK(D34)), AM$10>=D34, AM$10<=E34), "█", "")
F35: =IF(OR(ISBLANK(D35), ISBLANK(E35)), "", E35-D35+1) | H35: =IF(ISBLANK(B35), "", IF(G35=0, "Not Started", IF(G35=1, "Completed", "In Progress"))) | J35: =IF(AND(NOT(ISBLANK(D35)), J$10>=D35, J$10<=E35), "█", "") | K35: =IF(AND(NOT(ISBLANK(D35)), K$10>=D35, K$10<=E35), "█", "") | L35: =IF(AND(NOT(ISBLANK(D35)), L$10>=D35, L$10<=E35), "█", "") | M35: =IF(AND(NOT(ISBLANK(D35)), M$10>=D35, M$10<=E35), "█", "") | N35: =IF(AND(NOT(ISBLANK(D35)), N$10>=D35, N$10<=E35), "█", "") | O35: =IF(AND(NOT(ISBLANK(D35)), O$10>=D35, O$10<=E35), "█", "") | P35: =IF(AND(NOT(ISBLANK(D35)), P$10>=D35, P$10<=E35), "█", "") | Q35: =IF(AND(NOT(ISBLANK(D35)), Q$10>=D35, Q$10<=E35), "█", "") | R35: =IF(AND(NOT(ISBLANK(D35)), R$10>=D35, R$10<=E35), "█", "") | S35: =IF(AND(NOT(ISBLANK(D35)), S$10>=D35, S$10<=E35), "█", "") | T35: =IF(AND(NOT(ISBLANK(D35)), T$10>=D35, T$10<=E35), "█", "") | U35: =IF(AND(NOT(ISBLANK(D35)), U$10>=D35, U$10<=E35), "█", "") | V35: =IF(AND(NOT(ISBLANK(D35)), V$10>=D35, V$10<=E35), "█", "") | W35: =IF(AND(NOT(ISBLANK(D35)), W$10>=D35, W$10<=E35), "█", "") | X35: =IF(AND(NOT(ISBLANK(D35)), X$10>=D35, X$10<=E35), "█", "") | Y35: =IF(AND(NOT(ISBLANK(D35)), Y$10>=D35, Y$10<=E35), "█", "") | Z35: =IF(AND(NOT(ISBLANK(D35)), Z$10>=D35, Z$10<=E35), "█", "") | AA35: =IF(AND(NOT(ISBLANK(D35)), AA$10>=D35, AA$10<=E35), "█", "") | AB35: =IF(AND(NOT(ISBLANK(D35)), AB$10>=D35, AB$10<=E35), "█", "") | AC35: =IF(AND(NOT(ISBLANK(D35)), AC$10>=D35, AC$10<=E35), "█", "") | AD35: =IF(AND(NOT(ISBLANK(D35)), AD$10>=D35, AD$10<=E35), "█", "") | AE35: =IF(AND(NOT(ISBLANK(D35)), AE$10>=D35, AE$10<=E35), "█", "") | AF35: =IF(AND(NOT(ISBLANK(D35)), AF$10>=D35, AF$10<=E35), "█", "") | AG35: =IF(AND(NOT(ISBLANK(D35)), AG$10>=D35, AG$10<=E35), "█", "") | AH35: =IF(AND(NOT(ISBLANK(D35)), AH$10>=D35, AH$10<=E35), "█", "") | AI35: =IF(AND(NOT(ISBLANK(D35)), AI$10>=D35, AI$10<=E35), "█", "") | AJ35: =IF(AND(NOT(ISBLANK(D35)), AJ$10>=D35, AJ$10<=E35), "█", "") | AK35: =IF(AND(NOT(ISBLANK(D35)), AK$10>=D35, AK$10<=E35), "█", "") | AL35: =IF(AND(NOT(ISBLANK(D35)), AL$10>=D35, AL$10<=E35), "█", "") | AM35: =IF(AND(NOT(ISBLANK(D35)), AM$10>=D35, AM$10<=E35), "█", "")
F36: =IF(OR(ISBLANK(D36), ISBLANK(E36)), "", E36-D36+1) | H36: =IF(ISBLANK(B36), "", IF(G36=0, "Not Started", IF(G36=1, "Completed", "In Progress"))) | J36: =IF(AND(NOT(ISBLANK(D36)), J$10>=D36, J$10<=E36), "█", "") | K36: =IF(AND(NOT(ISBLANK(D36)), K$10>=D36, K$10<=E36), "█", "") | L36: =IF(AND(NOT(ISBLANK(D36)), L$10>=D36, L$10<=E36), "█", "") | M36: =IF(AND(NOT(ISBLANK(D36)), M$10>=D36, M$10<=E36), "█", "") | N36: =IF(AND(NOT(ISBLANK(D36)), N$10>=D36, N$10<=E36), "█", "") | O36: =IF(AND(NOT(ISBLANK(D36)), O$10>=D36, O$10<=E36), "█", "") | P36: =IF(AND(NOT(ISBLANK(D36)), P$10>=D36, P$10<=E36), "█", "") | Q36: =IF(AND(NOT(ISBLANK(D36)), Q$10>=D36, Q$10<=E36), "█", "") | R36: =IF(AND(NOT(ISBLANK(D36)), R$10>=D36, R$10<=E36), "█", "") | S36: =IF(AND(NOT(ISBLANK(D36)), S$10>=D36, S$10<=E36), "█", "") | T36: =IF(AND(NOT(ISBLANK(D36)), T$10>=D36, T$10<=E36), "█", "") | U36: =IF(AND(NOT(ISBLANK(D36)), U$10>=D36, U$10<=E36), "█", "") | V36: =IF(AND(NOT(ISBLANK(D36)), V$10>=D36, V$10<=E36), "█", "") | W36: =IF(AND(NOT(ISBLANK(D36)), W$10>=D36, W$10<=E36), "█", "") | X36: =IF(AND(NOT(ISBLANK(D36)), X$10>=D36, X$10<=E36), "█", "") | Y36: =IF(AND(NOT(ISBLANK(D36)), Y$10>=D36, Y$10<=E36), "█", "") | Z36: =IF(AND(NOT(ISBLANK(D36)), Z$10>=D36, Z$10<=E36), "█", "") | AA36: =IF(AND(NOT(ISBLANK(D36)), AA$10>=D36, AA$10<=E36), "█", "") | AB36: =IF(AND(NOT(ISBLANK(D36)), AB$10>=D36, AB$10<=E36), "█", "") | AC36: =IF(AND(NOT(ISBLANK(D36)), AC$10>=D36, AC$10<=E36), "█", "") | AD36: =IF(AND(NOT(ISBLANK(D36)), AD$10>=D36, AD$10<=E36), "█", "") | AE36: =IF(AND(NOT(ISBLANK(D36)), AE$10>=D36, AE$10<=E36), "█", "") | AF36: =IF(AND(NOT(ISBLANK(D36)), AF$10>=D36, AF$10<=E36), "█", "") | AG36: =IF(AND(NOT(ISBLANK(D36)), AG$10>=D36, AG$10<=E36), "█", "") | AH36: =IF(AND(NOT(ISBLANK(D36)), AH$10>=D36, AH$10<=E36), "█", "") | AI36: =IF(AND(NOT(ISBLANK(D36)), AI$10>=D36, AI$10<=E36), "█", "") | AJ36: =IF(AND(NOT(ISBLANK(D36)), AJ$10>=D36, AJ$10<=E36), "█", "") | AK36: =IF(AND(NOT(ISBLANK(D36)), AK$10>=D36, AK$10<=E36), "█", "") | AL36: =IF(AND(NOT(ISBLANK(D36)), AL$10>=D36, AL$10<=E36), "█", "") | AM36: =IF(AND(NOT(ISBLANK(D36)), AM$10>=D36, AM$10<=E36), "█", "")
